 * Serving Flask app "server" (lazy loading)
 * Environment: production
   WARNING: Do not use the development server in a production environment.
   Use a production WSGI server instead.
 * Debug mode: on
Traceback (most recent call last):
  File "server.py", line 690, in <module>
    app.run(debug = True, host = '0.0.0.0', port = 5000)
  File "/home/ubuntu/.local/lib/python3.6/site-packages/flask/app.py", line 943, in run
    run_simple(host, port, self, **options)
  File "/home/ubuntu/.local/lib/python3.6/site-packages/werkzeug/serving.py", line 795, in run_simple
    s.bind(get_sockaddr(hostname, port, address_family))
OSError: [Errno 98] Address already in use
 * Serving Flask app "server" (lazy loading)
 * Environment: production
   WARNING: Do not use the development server in a production environment.
   Use a production WSGI server instead.
 * Debug mode: on
 * Running on http://0.0.0.0:5000/ (Press CTRL+C to quit)
 * Restarting with stat
 * Debugger is active!
 * Debugger PIN: 132-771-476
 * Serving Flask app "server" (lazy loading)
 * Environment: production
   WARNING: Do not use the development server in a production environment.
   Use a production WSGI server instead.
 * Debug mode: on
 * Running on http://0.0.0.0:5000/ (Press CTRL+C to quit)
 * Restarting with stat
 * Debugger is active!
 * Debugger PIN: 132-771-476
27.7.25.254 - - [01/Mar/2019 16:31:10] "POST /api/v1/users HTTP/1.1" 200 -
27.7.25.254 - - [01/Mar/2019 16:32:15] "POST /api/v1/users HTTP/1.1" 500 -
Traceback (most recent call last):
  File "/home/ubuntu/.local/lib/python3.6/site-packages/flask/app.py", line 2309, in __call__
    return self.wsgi_app(environ, start_response)
  File "/home/ubuntu/.local/lib/python3.6/site-packages/flask/app.py", line 2295, in wsgi_app
    response = self.handle_exception(e)
  File "/home/ubuntu/.local/lib/python3.6/site-packages/flask/app.py", line 1741, in handle_exception
    reraise(exc_type, exc_value, tb)
  File "/home/ubuntu/.local/lib/python3.6/site-packages/flask/_compat.py", line 35, in reraise
    raise value
  File "/home/ubuntu/.local/lib/python3.6/site-packages/flask/app.py", line 2292, in wsgi_app
    response = self.full_dispatch_request()
  File "/home/ubuntu/.local/lib/python3.6/site-packages/flask/app.py", line 1815, in full_dispatch_request
    rv = self.handle_user_exception(e)
  File "/home/ubuntu/.local/lib/python3.6/site-packages/flask/app.py", line 1718, in handle_user_exception
    reraise(exc_type, exc_value, tb)
  File "/home/ubuntu/.local/lib/python3.6/site-packages/flask/_compat.py", line 35, in reraise
    raise value
  File "/home/ubuntu/.local/lib/python3.6/site-packages/flask/app.py", line 1813, in full_dispatch_request
    rv = self.dispatch_request()
  File "/home/ubuntu/.local/lib/python3.6/site-packages/flask/app.py", line 1799, in dispatch_request
    return self.view_functions[rule.endpoint](**req.view_args)
  File "/home/ubuntu/server.py", line 254, in addUser
    u_data = json.loads(request.data.decode())['username']
  File "/usr/lib/python3.6/json/__init__.py", line 354, in loads
    return _default_decoder.decode(s)
  File "/usr/lib/python3.6/json/decoder.py", line 339, in decode
    obj, end = self.raw_decode(s, idx=_w(s, 0).end())
  File "/usr/lib/python3.6/json/decoder.py", line 357, in raw_decode
    raise JSONDecodeError("Expecting value", s, err.value) from None
json.decoder.JSONDecodeError: Expecting value: line 1 column 1 (char 0)
27.7.25.254 - - [01/Mar/2019 16:33:14] "POST /api/v1/users HTTP/1.1" 200 -
27.7.25.254 - - [01/Mar/2019 16:33:30] "DELETE /api/v1/users/hrishi HTTP/1.1" 200 -
27.7.25.254 - - [01/Mar/2019 16:33:39] "DELETE /api/v1/users/abc HTTP/1.1" 200 -
27.7.25.254 - - [01/Mar/2019 16:41:34] "POST /api/v1/users HTTP/1.1" 200 -
27.7.25.254 - - [01/Mar/2019 16:42:03] "DELETE /api/v1/users/hrishi HTTP/1.1" 200 -
27.7.25.254 - - [01/Mar/2019 16:44:50] "POST /api/v1/users/hrishi HTTP/1.1" 405 -
27.7.25.254 - - [01/Mar/2019 16:44:55] "POST /api/v1/users HTTP/1.1" 200 -
27.7.25.254 - - [01/Mar/2019 16:45:02] "DELETE /api/v1/users/hrishi HTTP/1.1" 200 -
27.7.25.254 - - [01/Mar/2019 16:46:29] "POST /api/v1/users HTTP/1.1" 200 -
27.7.25.254 - - [01/Mar/2019 16:46:36] "DELETE /api/v1/users/hrishi HTTP/1.1" 200 -
49.206.10.177 - - [01/Mar/2019 16:54:07] "POST /api/v1/users HTTP/1.1" 500 -
Traceback (most recent call last):
  File "/home/ubuntu/.local/lib/python3.6/site-packages/flask/app.py", line 2309, in __call__
    return self.wsgi_app(environ, start_response)
  File "/home/ubuntu/.local/lib/python3.6/site-packages/flask/app.py", line 2295, in wsgi_app
    response = self.handle_exception(e)
  File "/home/ubuntu/.local/lib/python3.6/site-packages/flask/app.py", line 1741, in handle_exception
    reraise(exc_type, exc_value, tb)
  File "/home/ubuntu/.local/lib/python3.6/site-packages/flask/_compat.py", line 35, in reraise
    raise value
  File "/home/ubuntu/.local/lib/python3.6/site-packages/flask/app.py", line 2292, in wsgi_app
    response = self.full_dispatch_request()
  File "/home/ubuntu/.local/lib/python3.6/site-packages/flask/app.py", line 1815, in full_dispatch_request
    rv = self.handle_user_exception(e)
  File "/home/ubuntu/.local/lib/python3.6/site-packages/flask/app.py", line 1718, in handle_user_exception
    reraise(exc_type, exc_value, tb)
  File "/home/ubuntu/.local/lib/python3.6/site-packages/flask/_compat.py", line 35, in reraise
    raise value
  File "/home/ubuntu/.local/lib/python3.6/site-packages/flask/app.py", line 1813, in full_dispatch_request
    rv = self.dispatch_request()
  File "/home/ubuntu/.local/lib/python3.6/site-packages/flask/app.py", line 1799, in dispatch_request
    return self.view_functions[rule.endpoint](**req.view_args)
  File "/home/ubuntu/server.py", line 254, in addUser
    u_data = json.loads(request.data.decode())['username']
  File "/usr/lib/python3.6/json/__init__.py", line 354, in loads
    return _default_decoder.decode(s)
  File "/usr/lib/python3.6/json/decoder.py", line 339, in decode
    obj, end = self.raw_decode(s, idx=_w(s, 0).end())
  File "/usr/lib/python3.6/json/decoder.py", line 357, in raw_decode
    raise JSONDecodeError("Expecting value", s, err.value) from None
json.decoder.JSONDecodeError: Expecting value: line 1 column 1 (char 0)
49.206.10.177 - - [01/Mar/2019 16:55:45] "POST /api/v1/users HTTP/1.1" 500 -
Traceback (most recent call last):
  File "/home/ubuntu/.local/lib/python3.6/site-packages/flask/app.py", line 2309, in __call__
    return self.wsgi_app(environ, start_response)
  File "/home/ubuntu/.local/lib/python3.6/site-packages/flask/app.py", line 2295, in wsgi_app
    response = self.handle_exception(e)
  File "/home/ubuntu/.local/lib/python3.6/site-packages/flask/app.py", line 1741, in handle_exception
    reraise(exc_type, exc_value, tb)
  File "/home/ubuntu/.local/lib/python3.6/site-packages/flask/_compat.py", line 35, in reraise
    raise value
  File "/home/ubuntu/.local/lib/python3.6/site-packages/flask/app.py", line 2292, in wsgi_app
    response = self.full_dispatch_request()
  File "/home/ubuntu/.local/lib/python3.6/site-packages/flask/app.py", line 1815, in full_dispatch_request
    rv = self.handle_user_exception(e)
  File "/home/ubuntu/.local/lib/python3.6/site-packages/flask/app.py", line 1718, in handle_user_exception
    reraise(exc_type, exc_value, tb)
  File "/home/ubuntu/.local/lib/python3.6/site-packages/flask/_compat.py", line 35, in reraise
    raise value
  File "/home/ubuntu/.local/lib/python3.6/site-packages/flask/app.py", line 1813, in full_dispatch_request
    rv = self.dispatch_request()
  File "/home/ubuntu/.local/lib/python3.6/site-packages/flask/app.py", line 1799, in dispatch_request
    return self.view_functions[rule.endpoint](**req.view_args)
  File "/home/ubuntu/server.py", line 254, in addUser
    u_data = json.loads(request.data.decode())['username']
  File "/usr/lib/python3.6/json/__init__.py", line 354, in loads
    return _default_decoder.decode(s)
  File "/usr/lib/python3.6/json/decoder.py", line 339, in decode
    obj, end = self.raw_decode(s, idx=_w(s, 0).end())
  File "/usr/lib/python3.6/json/decoder.py", line 355, in raw_decode
    obj, end = self.scan_once(s, idx)
json.decoder.JSONDecodeError: Expecting property name enclosed in double quotes: line 1 column 2 (char 1)
49.206.10.177 - - [01/Mar/2019 16:57:04] "POST /api/v1/users HTTP/1.1" 500 -
Traceback (most recent call last):
  File "/home/ubuntu/.local/lib/python3.6/site-packages/flask/app.py", line 2309, in __call__
    return self.wsgi_app(environ, start_response)
  File "/home/ubuntu/.local/lib/python3.6/site-packages/flask/app.py", line 2295, in wsgi_app
    response = self.handle_exception(e)
  File "/home/ubuntu/.local/lib/python3.6/site-packages/flask/app.py", line 1741, in handle_exception
    reraise(exc_type, exc_value, tb)
  File "/home/ubuntu/.local/lib/python3.6/site-packages/flask/_compat.py", line 35, in reraise
    raise value
  File "/home/ubuntu/.local/lib/python3.6/site-packages/flask/app.py", line 2292, in wsgi_app
    response = self.full_dispatch_request()
  File "/home/ubuntu/.local/lib/python3.6/site-packages/flask/app.py", line 1815, in full_dispatch_request
    rv = self.handle_user_exception(e)
  File "/home/ubuntu/.local/lib/python3.6/site-packages/flask/app.py", line 1718, in handle_user_exception
    reraise(exc_type, exc_value, tb)
  File "/home/ubuntu/.local/lib/python3.6/site-packages/flask/_compat.py", line 35, in reraise
    raise value
  File "/home/ubuntu/.local/lib/python3.6/site-packages/flask/app.py", line 1813, in full_dispatch_request
    rv = self.dispatch_request()
  File "/home/ubuntu/.local/lib/python3.6/site-packages/flask/app.py", line 1799, in dispatch_request
    return self.view_functions[rule.endpoint](**req.view_args)
  File "/home/ubuntu/server.py", line 254, in addUser
    u_data = json.loads(request.data.decode())['username']
  File "/usr/lib/python3.6/json/__init__.py", line 354, in loads
    return _default_decoder.decode(s)
  File "/usr/lib/python3.6/json/decoder.py", line 339, in decode
    obj, end = self.raw_decode(s, idx=_w(s, 0).end())
  File "/usr/lib/python3.6/json/decoder.py", line 357, in raw_decode
    raise JSONDecodeError("Expecting value", s, err.value) from None
json.decoder.JSONDecodeError: Expecting value: line 1 column 2 (char 1)
49.206.10.177 - - [01/Mar/2019 16:57:20] "POST /api/v1/users HTTP/1.1" 500 -
Traceback (most recent call last):
  File "/home/ubuntu/.local/lib/python3.6/site-packages/flask/app.py", line 2309, in __call__
    return self.wsgi_app(environ, start_response)
  File "/home/ubuntu/.local/lib/python3.6/site-packages/flask/app.py", line 2295, in wsgi_app
    response = self.handle_exception(e)
  File "/home/ubuntu/.local/lib/python3.6/site-packages/flask/app.py", line 1741, in handle_exception
    reraise(exc_type, exc_value, tb)
  File "/home/ubuntu/.local/lib/python3.6/site-packages/flask/_compat.py", line 35, in reraise
    raise value
  File "/home/ubuntu/.local/lib/python3.6/site-packages/flask/app.py", line 2292, in wsgi_app
    response = self.full_dispatch_request()
  File "/home/ubuntu/.local/lib/python3.6/site-packages/flask/app.py", line 1815, in full_dispatch_request
    rv = self.handle_user_exception(e)
  File "/home/ubuntu/.local/lib/python3.6/site-packages/flask/app.py", line 1718, in handle_user_exception
    reraise(exc_type, exc_value, tb)
  File "/home/ubuntu/.local/lib/python3.6/site-packages/flask/_compat.py", line 35, in reraise
    raise value
  File "/home/ubuntu/.local/lib/python3.6/site-packages/flask/app.py", line 1813, in full_dispatch_request
    rv = self.dispatch_request()
  File "/home/ubuntu/.local/lib/python3.6/site-packages/flask/app.py", line 1799, in dispatch_request
    return self.view_functions[rule.endpoint](**req.view_args)
  File "/home/ubuntu/server.py", line 254, in addUser
    u_data = json.loads(request.data.decode())['username']
  File "/usr/lib/python3.6/json/__init__.py", line 354, in loads
    return _default_decoder.decode(s)
  File "/usr/lib/python3.6/json/decoder.py", line 339, in decode
    obj, end = self.raw_decode(s, idx=_w(s, 0).end())
  File "/usr/lib/python3.6/json/decoder.py", line 355, in raw_decode
    obj, end = self.scan_once(s, idx)
json.decoder.JSONDecodeError: Expecting property name enclosed in double quotes: line 1 column 2 (char 1)
49.206.10.177 - - [01/Mar/2019 16:58:25] "POST /api/v1/users HTTP/1.1" 200 -
49.206.10.177 - - [01/Mar/2019 17:00:04] "POST /api/v1/categories HTTP/1.1" 200 -
49.206.10.177 - - [01/Mar/2019 17:00:15] "POST /api/v1/categories HTTP/1.1" 200 -
49.206.10.177 - - [01/Mar/2019 17:00:32] "POST /api/v1/categories HTTP/1.1" 200 -
49.206.10.177 - - [01/Mar/2019 17:00:56] "POST /api/v1/categories HTTP/1.1" 200 -
 * Detected change in '/home/ubuntu/server.py', reloading
Receiving data....
abc sdasd
Receiving data....
Receiving data....
hrishi helasd0
Receiving data....
OBJECTIVE :  hrishi
Receiving data....
OBJECTIVE :  abc
Receiving data....
hrishi helasd0
Receiving data....
OBJECTIVE :  hrishi
Receiving data....
hrishi helasd0
Receiving data....
OBJECTIVE :  hrishi
Receiving data....
hrishi helasd0
Receiving data....
OBJECTIVE :  hrishi
Receiving data....
Receiving data....
Receiving data....
Receiving data....
Receiving data....
userName 3d725109c7e7c0bfb9d709836735b56d943d263f
Receiving category name
ell12
category Name is --> ell12
Receiving category name
23hell12
category Name is --> 23hell12
Receiving category name
123hell123
category Name is --> 123hell123
Receiving category name
23hell12
category Name is --> 23hell12
 * Restarting with stat
 * Debugger is active!
 * Debugger PIN: 132-771-476
 * Serving Flask app "server" (lazy loading)
 * Environment: production
   WARNING: Do not use the development server in a production environment.
   Use a production WSGI server instead.
 * Debug mode: on
 * Running on http://0.0.0.0:5000/ (Press CTRL+C to quit)
 * Restarting with stat
 * Debugger is active!
 * Debugger PIN: 132-771-476
27.7.25.254 - - [01/Mar/2019 18:24:06] "GET /api/v1/categories HTTP/1.1" 200 -
